<?xml version="1.0" ?>
<robot name="stembotx2" xmlns:xacro="http://www.ros.org/wiki/xacro">

<xacro:include filename="$(find stembotx2_description)/urdf/materials.xacro" />
<xacro:include filename="$(find stembotx2_description)/urdf/stembotx2.trans" />
<xacro:include filename="$(find stembotx2_description)/urdf/stembotx2.gazebo" />


<!-- <link name="base_footprint">
  <visual>
    <origin xyz="0 0 0" rpy="0 0 0"/>
    <geometry>
      <box size="0.001 0.001 0.001"/>
    </geometry>
    <material name="transparent">
      <color rgba="0 0 0 0"/>
    </material>
  </visual>
</link> -->

<link name="base_footprint"/>

<link name="base_link">
  <inertial>
    <origin xyz="0 0 0.015" rpy="0 0 0"/>
    <mass value="30"/>
    <inertia ixx="0.5" iyy="0.5" izz="0.8" ixy="0.0" iyz="0.0" ixz="0.0"/>
  </inertial>
  <visual>
    <origin xyz="0 0 0" rpy="0 0 0"/>
    <geometry>
      <mesh filename="file://$(find stembotx2_description)/meshes/base_link.stl" scale="0.001 0.001 0.001"/>
    </geometry>
    <material name="silver"/>
  </visual>
  <collision>
    <origin xyz="0 0 0" rpy="0 0 0"/>
    <geometry>
      <mesh filename="file://$(find stembotx2_description)/meshes/base_link.stl" scale="0.001 0.001 0.001"/>
    </geometry>
  </collision>
</link>

<link name="Agv_left_wheel_link_1">
  <inertial>
    <origin xyz="0 0 0" rpy="0 0 0"/>
    <mass value="1.5"/>
    <inertia ixx="0.001" iyy="0.001" izz="0.001" ixy="0.0" iyz="0.0" ixz="0.0"/>
  </inertial>
  <visual>
    <origin xyz="-0.081 -0.0 -0.035" rpy="0 0 0"/>
    <geometry>
      <mesh filename="file://$(find stembotx2_description)/meshes/Agv_left_wheel_link_1.stl" scale="0.001 0.001 0.001"/>
    </geometry>
    <material name="silver"/>
  </visual>
  <collision>
    <origin xyz="-0.081 -0.0 -0.035" rpy="0 0 0"/>
    <geometry>
      <mesh filename="file://$(find stembotx2_description)/meshes/Agv_left_wheel_link_1.stl" scale="0.001 0.001 0.001"/>
    </geometry>
  </collision>
</link>

<link name="Agv_right_wheel_link_1">
  <inertial>
    <origin xyz="0 0 0" rpy="0 0 0"/>
    <mass value="1.5"/>
    <inertia ixx="0.001" iyy="0.001" izz="0.001" ixy="0.0" iyz="0.0" ixz="0.0"/>
  </inertial>
  <visual>
    <origin xyz="0.082 -0.0 -0.035" rpy="0 0 0"/>
    <geometry>
      <mesh filename="file://$(find stembotx2_description)/meshes/Agv_right_wheel_link_1.stl" scale="0.001 0.001 0.001"/>
    </geometry>
    <material name="silver"/>
  </visual>
  <collision>
    <origin xyz="0.082 -0.0 -0.035" rpy="0 0 0"/>
    <geometry>
      <mesh filename="file://$(find stembotx2_description)/meshes/Agv_right_wheel_link_1.stl" scale="0.001 0.001 0.001"/>
    </geometry>
  </collision>
</link>

<link name="Agv_back_castor_wheel_link_1">
  <inertial>
    <origin xyz="0 0 -0.01" rpy="0 0 0"/>
    <mass value="0.5"/>
    <inertia ixx="0.0001" iyy="0.0001" izz="0.0001" ixy="0.0" iyz="0.0" ixz="0.0"/>
  </inertial>
  <visual>
    <origin xyz="-0.0 -0.135 -0.031" rpy="0 0 0"/>
    <geometry>
      <mesh filename="file://$(find stembotx2_description)/meshes/Agv_back_castor_wheel_link_1.stl" scale="0.001 0.001 0.001"/>
    </geometry>
    <material name="silver"/>
  </visual>
  <collision>
    <origin xyz="-0.0 -0.135 -0.031" rpy="0 0 0"/>
    <geometry>
      <mesh filename="file://$(find stembotx2_description)/meshes/Agv_back_castor_wheel_link_1.stl" scale="0.001 0.001 0.001"/>
    </geometry>
  </collision>
</link>

<link name="Agv_front_castor_wheel_link_1">
  <inertial>
    <origin xyz="0 0 -0.01" rpy="0 0 0"/>
    <mass value="0.5"/>
    <inertia ixx="0.0001" iyy="0.0001" izz="0.0001" ixy="0.0" iyz="0.0" ixz="0.0"/>
  </inertial>
  <visual>
    <origin xyz="-0.0 0.135 -0.031" rpy="0 0 0"/>
    <geometry>
      <mesh filename="file://$(find stembotx2_description)/meshes/Agv_front_castor_wheel_link_1.stl" scale="0.001 0.001 0.001"/>
    </geometry>
    <material name="silver"/>
  </visual>
  <collision>
    <origin xyz="-0.0 0.135 -0.031" rpy="0 0 0"/>
    <geometry>
      <mesh filename="file://$(find stembotx2_description)/meshes/Agv_front_castor_wheel_link_1.stl" scale="0.001 0.001 0.001"/>
    </geometry>
  </collision>
</link>

<link name="Agv_scan_link_1">
  <inertial>
    <origin xyz="3.6187644375762656e-18 1.3877787807814457e-17 0.010000000000000009" rpy="0 0 0"/>
    <mass value="0.3082687791334986"/>
    <inertia ixx="5.8e-05" iyy="5.8e-05" izz="9.6e-05" ixy="0.0" iyz="0.0" ixz="0.0"/>
  </inertial>
  <visual>
    <origin xyz="-0.0 -0.0485 -0.246" rpy="0 0 0"/>
    <geometry>
      <mesh filename="file://$(find stembotx2_description)/meshes/Agv_scan_link_1.stl" scale="0.001 0.001 0.001"/>
    </geometry>
    <material name="silver"/>
  </visual>
  <collision>
    <origin xyz="-0.0 -0.0485 -0.246" rpy="0 0 0"/>
    <geometry>
      <mesh filename="file://$(find stembotx2_description)/meshes/Agv_scan_link_1.stl" scale="0.001 0.001 0.001"/>
    </geometry>
  </collision>
</link>

<link name="agv_tof1_1">
  <inertial>
    <origin xyz="-1.3463482236436564e-06 -3.752646745708299e-06 0.0010000000000000009" rpy="0 0 0"/>
    <mass value="0.0001258791185545458"/>
    <inertia ixx="0.0" iyy="0.0" izz="0.0" ixy="0.0" iyz="0.0" ixz="-0.0"/>
  </inertial>
  <visual>
    <origin xyz="0.057783 0.1395 -0.181" rpy="0 0 0"/>
    <geometry>
      <mesh filename="file://$(find stembotx2_description)/meshes/agv_tof1_1.stl" scale="0.001 0.001 0.001"/>
    </geometry>
    <material name="silver"/>
  </visual>
  <collision>
    <origin xyz="0.057783 0.1395 -0.181" rpy="0 0 0"/>
    <geometry>
      <mesh filename="file://$(find stembotx2_description)/meshes/agv_tof1_1.stl" scale="0.001 0.001 0.001"/>
    </geometry>
  </collision>
</link>

<link name="agv_tof5_1">
  <inertial>
    <origin xyz="1.3463482236436564e-06 -3.7526467457360546e-06 0.0010000000000000009" rpy="0 0 0"/>
    <mass value="0.00012587911855454543"/>
    <inertia ixx="0.0" iyy="0.0" izz="0.0" ixy="-0.0" iyz="-0.0" ixz="0.0"/>
  </inertial>
  <visual>
    <origin xyz="-0.057783 0.1395 -0.181" rpy="0 0 0"/>
    <geometry>
      <mesh filename="file://$(find stembotx2_description)/meshes/agv_tof5_1.stl" scale="0.001 0.001 0.001"/>
    </geometry>
    <material name="silver"/>
  </visual>
  <collision>
    <origin xyz="-0.057783 0.1395 -0.181" rpy="0 0 0"/>
    <geometry>
      <mesh filename="file://$(find stembotx2_description)/meshes/agv_tof5_1.stl" scale="0.001 0.001 0.001"/>
    </geometry>
  </collision>
</link>

<link name="agv_tof6_1">
  <inertial>
    <origin xyz="-4.7737763238242525e-06 1.4967252291981122e-11 0.0010000000000000286" rpy="0 0 0"/>
    <mass value="0.00012587911949657815"/>
    <inertia ixx="0.0" iyy="0.0" izz="0.0" ixy="-0.0" iyz="0.0" ixz="-0.0"/>
  </inertial>
  <visual>
    <origin xyz="0.150993 -0.0 -0.181" rpy="0 0 0"/>
    <geometry>
      <mesh filename="file://$(find stembotx2_description)/meshes/agv_tof6_1.stl" scale="0.001 0.001 0.001"/>
    </geometry>
    <material name="silver"/>
  </visual>
  <collision>
    <origin xyz="0.150993 -0.0 -0.181" rpy="0 0 0"/>
    <geometry>
      <mesh filename="file://$(find stembotx2_description)/meshes/agv_tof6_1.stl" scale="0.001 0.001 0.001"/>
    </geometry>
  </collision>
</link>

<link name="agv_tof4_1">
  <inertial>
    <origin xyz="-1.3463482236436564e-06 3.752646745708299e-06 0.0010000000000000286" rpy="0 0 0"/>
    <mass value="0.00012587911855454584"/>
    <inertia ixx="0.0" iyy="0.0" izz="0.0" ixy="-0.0" iyz="0.0" ixz="-0.0"/>
  </inertial>
  <visual>
    <origin xyz="0.057783 -0.1395 -0.181" rpy="0 0 0"/>
    <geometry>
      <mesh filename="file://$(find stembotx2_description)/meshes/agv_tof4_1.stl" scale="0.001 0.001 0.001"/>
    </geometry>
    <material name="silver"/>
  </visual>
  <collision>
    <origin xyz="0.057783 -0.1395 -0.181" rpy="0 0 0"/>
    <geometry>
      <mesh filename="file://$(find stembotx2_description)/meshes/agv_tof4_1.stl" scale="0.001 0.001 0.001"/>
    </geometry>
  </collision>
</link>

<link name="agv_tof3_1">
  <inertial>
    <origin xyz="1.3463482236436564e-06 3.752646745708299e-06 0.0010000000000000009" rpy="0 0 0"/>
    <mass value="0.00012587911855454543"/>
    <inertia ixx="0.0" iyy="0.0" izz="0.0" ixy="0.0" iyz="0.0" ixz="0.0"/>
  </inertial>
  <visual>
    <origin xyz="-0.057783 -0.1395 -0.181" rpy="0 0 0"/>
    <geometry>
      <mesh filename="file://$(find stembotx2_description)/meshes/agv_tof3_1.stl" scale="0.001 0.001 0.001"/>
    </geometry>
    <material name="silver"/>
  </visual>
  <collision>
    <origin xyz="-0.057783 -0.1395 -0.181" rpy="0 0 0"/>
    <geometry>
      <mesh filename="file://$(find stembotx2_description)/meshes/agv_tof3_1.stl" scale="0.001 0.001 0.001"/>
    </geometry>
  </collision>
</link>

<link name="agv_tof2_1">
  <inertial>
    <origin xyz="4.773776323796497e-06 1.4967246071641936e-11 0.0010000000000000009" rpy="0 0 0"/>
    <mass value="0.00012587911949657888"/>
    <inertia ixx="0.0" iyy="0.0" izz="0.0" ixy="0.0" iyz="-0.0" ixz="0.0"/>
  </inertial>
  <visual>
    <origin xyz="-0.150993 -0.0 -0.181" rpy="0 0 0"/>
    <geometry>
      <mesh filename="file://$(find stembotx2_description)/meshes/agv_tof2_1.stl" scale="0.001 0.001 0.001"/>
    </geometry>
    <material name="silver"/>
  </visual>
  <collision>
    <origin xyz="-0.150993 -0.0 -0.181" rpy="0 0 0"/>
    <geometry>
      <mesh filename="file://$(find stembotx2_description)/meshes/agv_tof2_1.stl" scale="0.001 0.001 0.001"/>
    </geometry>
  </collision>
</link>

<!-- <joint name="base_footprint_joint" type="fixed">
  <origin xyz="0 0 0.035" rpy="0 0 0"/>
  <parent link="base_footprint"/>
  <child link="base_link"/>
</joint> -->

<joint name="base_footprint_joint" type="fixed">
  <origin xyz="0 0 0.035" rpy="0 0 0"/>
  <parent link="base_footprint"/>
  <child link="base_link"/>
</joint>

<joint name="left_wheel_joint" type="continuous">
  <origin xyz="0.081 0.0 0.035" rpy="0 0 0"/>
  <parent link="base_link"/>
  <child link="Agv_left_wheel_link_1"/>
  <axis xyz="0.0 1.0 0.0"/>
</joint>

<joint name="right_wheel_joint" type="continuous">
  <origin xyz="-0.082 0.0 0.035" rpy="0 0 0"/>
  <parent link="base_link"/>
  <child link="Agv_right_wheel_link_1"/>
  <axis xyz="0.0 1.0 0.0"/>
</joint>

<joint name="back_castor_joint" type="fixed">
  <origin xyz="0.0 0.135 0.031" rpy="0 0 0"/>
  <parent link="base_link"/>
  <child link="Agv_back_castor_wheel_link_1"/>
</joint>

<joint name="front_castor_joint" type="fixed">
  <origin xyz="0.0 -0.135 0.031" rpy="0 0 0"/>
  <parent link="base_link"/>
  <child link="Agv_front_castor_wheel_link_1"/>
</joint>

<joint name="Rigid 10" type="fixed">
  <origin xyz="0.0 0.0485 0.246" rpy="0 0 0"/>
  <parent link="base_link"/>
  <child link="Agv_scan_link_1"/>
</joint>

<joint name="Rigid 11" type="fixed">
  <origin xyz="-0.057783 -0.1395 0.181" rpy="0 0 0"/>
  <parent link="base_link"/>
  <child link="agv_tof1_1"/>
</joint>

<joint name="Rigid 12" type="fixed">
  <origin xyz="0.057783 -0.1395 0.181" rpy="0 0 0"/>
  <parent link="base_link"/>
  <child link="agv_tof5_1"/>
</joint>

<joint name="Rigid 13" type="fixed">
  <origin xyz="-0.150993 0.0 0.181" rpy="0 0 0"/>
  <parent link="base_link"/>
  <child link="agv_tof6_1"/>
</joint>

<joint name="Rigid 14" type="fixed">
  <origin xyz="-0.057783 0.1395 0.181" rpy="0 0 0"/>
  <parent link="base_link"/>
  <child link="agv_tof4_1"/>
</joint>

<joint name="Rigid 15" type="fixed">
  <origin xyz="0.057783 0.1395 0.181" rpy="0 0 0"/>
  <parent link="base_link"/>
  <child link="agv_tof3_1"/>
</joint>

<joint name="Rigid 16" type="fixed">
  <origin xyz="0.150993 0.0 0.181" rpy="0 0 0"/>
  <parent link="base_link"/>
  <child link="agv_tof2_1"/>
</joint>

<gazebo>
      <plugin name="differential_drive_controller" filename="libgazebo_ros_diff_drive.so">
      <ros>
        <remapping>odom:=odom/unfiltered</remapping>
      </ros>
        <updateRate>50</updateRate>
        <left_joint>left_wheel_joint</left_joint>
        <right_joint>right_wheel_joint</right_joint>
        <wheel_separation>0.163</wheel_separation>
        <wheel_diameter>0.075</wheel_diameter>
        <max_wheel_acceleration>1.0</max_wheel_acceleration>
        <max_wheel_torque>20</max_wheel_torque>
        <robot_base_frame>base_link</robot_base_frame>
        <publish_odom>true</publish_odom>
        <publish_odom_tf>true</publish_odom_tf>
        <publish_wheel_tf>true</publish_wheel_tf>
        <odometry_frame>odom</odometry_frame>
      </plugin>
</gazebo>

</robot>
